<?xml version="1.0" ?>
<!-- =================================================================================== -->
<!-- |    This document was autogenerated by xacro from sara_dual_arms.xacro           | -->
<!-- |    EDITING THIS FILE BY HAND IS NOT RECOMMENDED                                 | -->
<!-- =================================================================================== -->
<robot name="tb3_sara">
    <transmission name="tran1">
        <type>transmission_interface/SimpleTransmission</type>
        <joint name="joint1">
            <hardwareInterface>hardware_interface/PositionJointInterface</hardwareInterface>
        </joint>
        <actuator name="motor1">
            <hardwareInterface>hardware_interface/PositionJointInterface</hardwareInterface>
            <mechanicalReduction>1</mechanicalReduction>
        </actuator>
    </transmission>
    <transmission name="tran2">
        <type>transmission_interface/SimpleTransmission</type>
        <joint name="joint2">
            <hardwareInterface>hardware_interface/PositionJointInterface</hardwareInterface>
        </joint>
        <actuator name="motor2">
            <hardwareInterface>hardware_interface/PositionJointInterface</hardwareInterface>
            <mechanicalReduction>1</mechanicalReduction>
        </actuator>
    </transmission>
    <transmission name="tran3">
        <type>transmission_interface/SimpleTransmission</type>
        <joint name="joint3">
            <hardwareInterface>hardware_interface/PositionJointInterface</hardwareInterface>
        </joint>
        <actuator name="motor3">
            <hardwareInterface>hardware_interface/PositionJointInterface</hardwareInterface>
            <mechanicalReduction>1</mechanicalReduction>
        </actuator>
    </transmission>
    <transmission name="tran4">
        <type>transmission_interface/SimpleTransmission</type>
        <joint name="joint4">
            <hardwareInterface>hardware_interface/PositionJointInterface</hardwareInterface>
        </joint>
        <actuator name="motor4">
            <hardwareInterface>hardware_interface/PositionJointInterface</hardwareInterface>
            <mechanicalReduction>1</mechanicalReduction>
        </actuator>
    </transmission>
    <transmission name="tran5">
        <type>transmission_interface/SimpleTransmission</type>
        <joint name="joint5">
            <hardwareInterface>hardware_interface/PositionJointInterface</hardwareInterface>
        </joint>
        <actuator name="motor5">
            <hardwareInterface>hardware_interface/PositionJointInterface</hardwareInterface>
            <mechanicalReduction>1</mechanicalReduction>
        </actuator>
    </transmission>
    <transmission name="tran6">
        <type>transmission_interface/SimpleTransmission</type>
        <joint name="joint6">
            <hardwareInterface>hardware_interface/PositionJointInterface</hardwareInterface>
        </joint>
        <actuator name="motor6">
            <hardwareInterface>hardware_interface/PositionJointInterface</hardwareInterface>
            <mechanicalReduction>1</mechanicalReduction>
        </actuator>
    </transmission>
    <transmission name="tran7">
        <type>transmission_interface/SimpleTransmission</type>
        <joint name="gripper">
            <hardwareInterface>hardware_interface/EffortJointInterface</hardwareInterface>
        </joint>
        <actuator name="motor7">
            <hardwareInterface>hardware_interface/EffortJointInterface</hardwareInterface>
            <mechanicalReduction>1</mechanicalReduction>
        </actuator>
    </transmission>
    <transmission name="tran8">
        <type>transmission_interface/SimpleTransmission</type>
        <joint name="gripper_sub">
            <hardwareInterface>hardware_interface/EffortJointInterface</hardwareInterface>
        </joint>
        <actuator name="motor8">
            <hardwareInterface>hardware_interface/EffortJointInterface</hardwareInterface>
            <mechanicalReduction>1</mechanicalReduction>
        </actuator>
    </transmission>
    <!-- Init colour -->
    <material name="black">
        <color rgba="0.0 0.0 0.0 1.0" />
    </material>
    <material name="dark">
        <color rgba="0.3 0.3 0.3 1.0" />
    </material>
    <material name="light_black">
        <color rgba="0.4 0.4 0.4 1.0" />
    </material>
    <material name="blue">
        <color rgba="0.0 0.0 0.8 1.0" />
    </material>
    <material name="green">
        <color rgba="0.0 0.8 0.0 1.0" />
    </material>
    <material name="grey">
        <color rgba="0.5 0.5 0.5 1.0" />
    </material>
    <material name="orange">
        <color rgba="1.0 0.4235294117647059 0.0392156862745098 1.0" />
    </material>
    <material name="brown">
        <color rgba="0.8705882352941177 0.8117647058823529 0.7647058823529411 1.0" />
    </material>
    <material name="red">
        <color rgba="0.8 0.0 0.0 1.0" />
    </material>
    <material name="white">
        <color rgba="1.0 1.0 1.0 1.0" />
    </material>
    <!--<xacro:include filename="$(find tb3mm_6dof)/urdf/tb3_for_om_d435.gazebo.xacro"/> -->
    <!--<xacro:include filename="$(find realsense2_description)/urdf/_d435.urdf.xacro" />-->
    <!--<xacro:include filename="$(find tb3mm_6dof)/urdf/tb3_for_om_d435.urdf.xacro"/> -->
    <!--<xacro:include filename="$(find tb3mm_6dof)/urdf/sara.urdf.xacro"/>-->
    <!--<xacro:include filename="$(find turtlebot3_description)/urdf/turtlebot3_waffle_pi_for_open_manipulator.urdf.xacro"/>-->
    <link name="base">
        <visual>
            <origin rpy="0 0 0" xyz="0 0 0" />
            <geometry>
                <box size="2 2 0.2" />
            </geometry>
            <material name="White">
                <color rgba="1.0 1.0 1.0 1.0" />
            </material>
        </visual>
        <collision>
            <origin rpy="0 0 0" xyz="0 0 0" />
            <geometry>
                <box size="2 2 0.2" />
            </geometry>
        </collision>
        <inertial>
            <origin rpy="0 0 0" xyz="0 0 0" />
            <mass value="5.0" />
            <inertia ixx="0.01" ixy="0.0" ixz="0.0" iyy="0.01" iyz="0.0" izz="0.01" />
        </inertial>
    </link>
    <!-- sara_1 arm을 base에 고정 -->
    <joint name="sara_1_base_joint" type="fixed">
        <parent link="base" />
        <child link="sara_1_link1" />
        <origin rpy="0 0 0" xyz="0.5 0.0 0.2" />
    </joint>
    <!-- sara_2 arm을 base에 고정 -->
    <joint name="sara_2_base_joint" type="fixed">
        <parent link="base" />
        <child link="sara_2_link1" />
        <origin rpy="0 0 0" xyz="-0.5 0.0 0.2" />
    </joint>
    <!-- Link 1 -->
    <link name="sara_1_link1">
        <visual>
            <origin rpy="0 0 0" xyz="0 0 0" />
            <geometry>
                <mesh filename="package://open_manipulator_6dof_description/meshes/chain_link1.stl" scale="0.001 0.001 0.001" />
            </geometry>
            <material name="grey" />
        </visual>
        <collision>
            <origin rpy="0 0 0" xyz="0 0 0" />
            <geometry>
                <mesh filename="package://open_manipulator_6dof_description/meshes/chain_link1.stl" scale="0.001 0.001 0.001" />
            </geometry>
        </collision>
        <inertial>
            <origin xyz="3.0876154e-04 0.0000000e+00 -1.2176461e-04" rpy="0 0 0" />
            <mass value="7.9119962e-02" />
            <inertia ixx="1.2505234e-05" ixy="0.0" ixz="-1.7855208e-07" iyy="2.1898364e-05" iyz="0.0" izz="1.9267361e-05" />
        </inertial>
    </link>
    <!-- Joint 1 -->
    <joint name="sara_1_joint1" type="revolute">
        <parent link="sara_1_link1" />
        <child link="sara_1_link2" />
        <origin rpy="0 0 0" xyz="0.012 0.0 0.017" />
        <axis xyz="0 0 1" />
        <limit effort="1" lower="-2.827433388230814" upper="2.827433388230814" velocity="4.8" />
    </joint>
    <!--  Link 2 -->
    <link name="sara_1_link2">
        <visual>
            <origin rpy="0 0 0" xyz="0 0 0.019" />
            <geometry>
                <mesh filename="package://open_manipulator_6dof_description/meshes/chain_link2.stl" scale="0.001 0.001 0.001" />
            </geometry>
            <material name="grey" />
        </visual>
        <collision>
            <origin rpy="0 0 0" xyz="0 0 0.019" />
            <geometry>
                <mesh filename="package://open_manipulator_6dof_description/meshes/chain_link2.stl" scale="0.001 0.001 0.001" />
            </geometry>
        </collision>
        <inertial>
            <origin xyz="-3.0184870e-04 5.4043684e-04 0.047433463999999995" rpy="0 0 0" />
            <mass value="9.8406837e-02" />
            <inertia ixx="3.4543422e-05" ixy="-1.6031095e-08" ixz="-3.8375155e-07" iyy="3.2689329e-05" iyz="2.8511935e-08" izz="1.8850320e-05" />
        </inertial>
    </link>
    <!--  Joint 2 -->
    <joint name="sara_1_joint2" type="revolute">
        <parent link="sara_1_link2" />
        <child link="sara_1_link3" />
        <origin rpy="0 0 0" xyz="0.0 0.0 0.0595" />
        <axis xyz="0 1 0" />
        <limit effort="1" lower="-2.0420352248333655" upper="2.1048670779051615" velocity="4.8" />
    </joint>
    <!--  Link 3 -->
    <link name="sara_1_link3">
        <visual>
            <origin rpy="0 0 0" xyz="0 0 0" />
            <geometry>
                <mesh filename="package://open_manipulator_6dof_description/meshes/chain_link3.stl" scale="0.001 0.001 0.001" />
            </geometry>
            <material name="grey" />
        </visual>
        <collision>
            <origin rpy="0 0 0" xyz="0 0 0" />
            <geometry>
                <mesh filename="package://open_manipulator_6dof_description/meshes/chain_link3.stl" scale="0.001 0.001 0.001" />
            </geometry>
        </collision>
        <inertial>
            <origin xyz="0 0 0" rpy="0 0 0" />
            <mass value="0.131" />
            <inertia ixx="0.1" ixy="0.0" ixz="0.0" iyy="0.1" iyz="0.0" izz="0.1" />
        </inertial>
    </link>
    <!--  Joint 3 -->
    <joint name="sara_1_joint3" type="revolute">
        <parent link="sara_1_link3" />
        <child link="sara_1_link4" />
        <origin rpy="0 0 0" xyz="0.0 0 0.124" />
        <axis xyz="0 1 0" />
        <limit effort="1" lower="-1.8849555921538759" upper="2.1362830044410597" velocity="4.8" />
    </joint>
    <!--  Link 4 -->
    <link name="sara_1_link4">
        <visual>
            <origin rpy="0 0 0" xyz="0 0 0" />
            <geometry>
                <mesh filename="package://open_manipulator_6dof_description/meshes/chain_link4.stl" scale="0.001 0.001 0.001" />
            </geometry>
            <material name="grey" />
        </visual>
        <collision>
            <origin rpy="0 0 0" xyz="0 0 0" />
            <geometry>
                <mesh filename="package://open_manipulator_6dof_description/meshes/chain_link4.stl" scale="0.001 0.001 0.001" />
            </geometry>
        </collision>
        <inertial>
            <origin xyz="0 0 0" rpy="0 0 0" />
            <mass value="0.098" />
            <inertia ixx="0.1" ixy="0.0" ixz="0.0" iyy="0.1" iyz="0.0" izz="0.1" />
        </inertial>
    </link>
    <!--  Joint 4 -->
    <joint name="sara_1_joint4" type="revolute">
        <parent link="sara_1_link4" />
        <child link="sara_1_link5" />
        <origin rpy="0 0 0" xyz="0.0 0.0 0.045" />
        <axis xyz="0 0 1" />
        <limit effort="1" lower="-2.827433388230814" upper="2.827433388230814" velocity="4.8" />
    </joint>
    <!--  Link 5 -->
    <link name="sara_1_link5">
        <visual>
            <origin rpy="0 0 0" xyz="0 0 0.019" />
            <geometry>
                <mesh filename="package://open_manipulator_6dof_description/meshes/chain_link5.stl" scale="0.001 0.001 0.001" />
            </geometry>
            <material name="grey" />
        </visual>
        <collision>
            <origin rpy="0 0 0" xyz="0 0 0.019" />
            <geometry>
                <mesh filename="package://open_manipulator_6dof_description/meshes/chain_link5.stl" scale="0.001 0.001 0.001" />
            </geometry>
        </collision>
        <inertial>
            <origin xyz="0 0 0" rpy="0 0 0" />
            <mass value="0.098" />
            <inertia ixx="0.1" ixy="0.0" ixz="0.0" iyy="0.1" iyz="0.0" izz="0.1" />
        </inertial>
    </link>
    <!--  Joint 5 -->
    <joint name="sara_1_joint5" type="revolute">
        <parent link="sara_1_link5" />
        <child link="sara_1_link6" />
        <origin rpy="0 0 0" xyz="0.0 0.0 0.0595" />
        <axis xyz="0 1 0" />
        <limit effort="1" lower="-1.9792033717615696" upper="2.1048670779051615" velocity="4.8" />
    </joint>
    <!--  Link 6 -->
    <link name="sara_1_link6">
        <visual>
            <origin rpy="0 0 0" xyz="0 0 0.0" />
            <geometry>
                <mesh filename="package://open_manipulator_6dof_description/meshes/chain_link6.stl" scale="0.001 0.001 0.001" />
            </geometry>
            <material name="grey" />
        </visual>
        <collision>
            <origin rpy="0 0 0" xyz="0 0 0.0" />
            <geometry>
                <mesh filename="package://open_manipulator_6dof_description/meshes/chain_link6.stl" scale="0.001 0.001 0.001" />
            </geometry>
        </collision>
        <inertial>
            <origin xyz="0 0 0" rpy="0 0 0" />
            <mass value="0.033" />
            <inertia ixx="0.1" ixy="0.0" ixz="0.0" iyy="0.1" iyz="0.0" izz="0.1" />
        </inertial>
        <inertial>
            <origin xyz="4.4206755e-02 3.6839985e-07 8.9142216e-03" />
            <mass value="1.4327573e-01" />
            <inertia ixx="8.0870749e-05" ixy="0.0" ixz="-1.0157896e-06" iyy="7.5980465e-05" iyz="0.0" izz="9.3127351e-05" />
        </inertial>
    </link>
    <!--  Joint 6 -->
    <joint name="sara_1_joint6" type="revolute">
        <parent link="sara_1_link6" />
        <child link="sara_1_link7" />
        <origin rpy="0 0 0" xyz="0.0 0.0 0.0475" />
        <axis xyz="0 0 1" />
        <limit effort="1" lower="-2.827433388230814" upper="2.827433388230814" velocity="4.8" />
    </joint>
    <!--  Link 7 -->
    <link name="sara_1_link7">
        <visual>
            <origin rpy="0 0 0" xyz="0 0 0.0" />
            <geometry>
                <mesh filename="package://open_manipulator_6dof_description/meshes/chain_link7.stl" scale="0.001 0.001 0.001" />
            </geometry>
            <!-- <material name="grey"/> -->
        </visual>
        <collision>
            <origin rpy="0 0 0" xyz="0 0 0.0" />
            <geometry>
                <mesh filename="package://open_manipulator_6dof_description/meshes/chain_link7.stl" scale="0.001 0.001 0.001" />
            </geometry>
        </collision>
        <inertial>
            <origin xyz="4.4206755e-02 3.6839985e-07 8.9142216e-03" rpy="0 0 0" />
            <mass value="1.4327573e-01" />
            <inertia ixx="8.0870749e-05" ixy="0.0" ixz="-1.0157896e-06" iyy="7.5980465e-05" iyz="0.0" izz="9.3127351e-05" />
        </inertial>
    </link>
    <!--  Gripper link -->
    <link name="sara_1_gripper_link">
        <visual>
            <origin rpy="0 0 0" xyz="0.0 0.0 0" />
            <geometry>
                <mesh filename="package://open_manipulator_6dof_description/meshes/chain_link_grip_l.stl" scale="0.001 0.001 0.001" />
            </geometry>
            <material name="grey" />
        </visual>
        <collision>
            <origin rpy="0 0 0" xyz="0.0 0.0 0" />
            <geometry>
                <mesh filename="package://open_manipulator_6dof_description/meshes/chain_link_grip_l.stl" scale="0.001 0.001 0.001" />
            </geometry>
        </collision>
        <inertial>
            <origin xyz="0 0 0" rpy="0 0 0" />
            <mass value="1.0e-03" />
            <inertia ixx="1.0e-03" ixy="0.0" ixz="0.0" iyy="1.0e-03" iyz="0.0" izz="1.0e-03" />
        </inertial>
    </link>
    <!--  Gripper joint -->
    <joint name="sara_1_gripper" type="prismatic">
        <parent link="sara_1_link7" />
        <child link="sara_1_gripper_link" />
        <origin rpy="0 0 0" xyz="0.0 0.021 0.0707" />
        <axis xyz="0 1 0" />
        <limit effort="1" lower="-0.010" upper="0.019" velocity="4.8" />
    </joint>
    <!--  Gripper link sub -->
    <link name="sara_1_gripper_link_sub">
        <visual>
            <origin rpy="0 0 0" xyz="0.0 -0.0 0" />
            <geometry>
                <mesh filename="package://open_manipulator_6dof_description/meshes/chain_link_grip_r.stl" scale="0.001 0.001 0.001" />
            </geometry>
            <material name="grey" />
        </visual>
        <collision>
            <origin rpy="0 0 0" xyz="0.0 -0.0 0" />
            <geometry>
                <mesh filename="package://open_manipulator_6dof_description/meshes/chain_link_grip_r.stl" scale="0.001 0.001 0.001" />
            </geometry>
        </collision>
        <inertial>
            <origin xyz="0 0 0" rpy="0 0 0" />
            <mass value="1.0e-03" />
            <inertia ixx="1.0e-03" ixy="0.0" ixz="0.0" iyy="1.0e-03" iyz="0.0" izz="1.0e-03" />
        </inertial>
    </link>
    <!--  Gripper joint sub -->
    <joint name="sara_1_gripper_sub" type="prismatic">
        <parent link="sara_1_link7" />
        <child link="sara_1_gripper_link_sub" />
        <origin rpy="0 0 0" xyz="0.0 -0.021 0.0707" />
        <axis xyz="0 -1 0" />
        <limit effort="1" lower="-0.010" upper="0.019" velocity="4.8" />
        <mimic joint="sara_1_gripper" multiplier="1" />
    </joint>
    <!-- end effector joint -->
    <joint name="sara_1_end_effector_joint" type="fixed">
        <origin rpy="0 0 0" xyz="0.0 0.0 0.115" />
        <parent link="sara_1_link7" />
        <child link="sara_1_end_effector_link" />
    </joint>
    <!-- end effector link -->
    <link name="sara_1_end_effector_link">
        <visual>
            <origin rpy="0 0 0" xyz="0 0 0" />
            <geometry>
                <box size="0.01 0.01 0.01" />
            </geometry>
            <material name="red" />
        </visual>
        <inertial>
            <origin xyz="0 0 0" />
            <mass value="1.0e-03" />
            <inertia ixx="1.0e-03" ixy="0.0" ixz="0.0" iyy="1.0e-03" iyz="0.0" izz="1.0e-03" />
        </inertial>
    </link>
    <!-- Link 1 -->
    <link name="sara_2_link1">
        <visual>
            <origin rpy="0 0 0" xyz="0 0 0" />
            <geometry>
                <mesh filename="package://open_manipulator_6dof_description/meshes/chain_link1.stl" scale="0.001 0.001 0.001" />
            </geometry>
            <material name="grey" />
        </visual>
        <collision>
            <origin rpy="0 0 0" xyz="0 0 0" />
            <geometry>
                <mesh filename="package://open_manipulator_6dof_description/meshes/chain_link1.stl" scale="0.001 0.001 0.001" />
            </geometry>
        </collision>
        <inertial>
            <origin xyz="3.0876154e-04 0.0000000e+00 -1.2176461e-04" rpy="0 0 0" />
            <mass value="7.9119962e-02" />
            <inertia ixx="1.2505234e-05" ixy="0.0" ixz="-1.7855208e-07" iyy="2.1898364e-05" iyz="0.0" izz="1.9267361e-05" />
        </inertial>
    </link>
    <!-- Joint 1 -->
    <joint name="sara_2_joint1" type="revolute">
        <parent link="sara_2_link1" />
        <child link="sara_2_link2" />
        <origin rpy="0 0 0" xyz="0.012 0.0 0.017" />
        <axis xyz="0 0 1" />
        <limit effort="1" lower="-2.827433388230814" upper="2.827433388230814" velocity="4.8" />
    </joint>
    <!--  Link 2 -->
    <link name="sara_2_link2">
        <visual>
            <origin rpy="0 0 0" xyz="0 0 0.019" />
            <geometry>
                <mesh filename="package://open_manipulator_6dof_description/meshes/chain_link2.stl" scale="0.001 0.001 0.001" />
            </geometry>
            <material name="grey" />
        </visual>
        <collision>
            <origin rpy="0 0 0" xyz="0 0 0.019" />
            <geometry>
                <mesh filename="package://open_manipulator_6dof_description/meshes/chain_link2.stl" scale="0.001 0.001 0.001" />
            </geometry>
        </collision>
        <inertial>
            <origin xyz="-3.0184870e-04 5.4043684e-04 0.047433463999999995" rpy="0 0 0" />
            <mass value="9.8406837e-02" />
            <inertia ixx="3.4543422e-05" ixy="-1.6031095e-08" ixz="-3.8375155e-07" iyy="3.2689329e-05" iyz="2.8511935e-08" izz="1.8850320e-05" />
        </inertial>
    </link>
    <!--  Joint 2 -->
    <joint name="sara_2_joint2" type="revolute">
        <parent link="sara_2_link2" />
        <child link="sara_2_link3" />
        <origin rpy="0 0 0" xyz="0.0 0.0 0.0595" />
        <axis xyz="0 1 0" />
        <limit effort="1" lower="-2.0420352248333655" upper="2.1048670779051615" velocity="4.8" />
    </joint>
    <!--  Link 3 -->
    <link name="sara_2_link3">
        <visual>
            <origin rpy="0 0 0" xyz="0 0 0" />
            <geometry>
                <mesh filename="package://open_manipulator_6dof_description/meshes/chain_link3.stl" scale="0.001 0.001 0.001" />
            </geometry>
            <material name="grey" />
        </visual>
        <collision>
            <origin rpy="0 0 0" xyz="0 0 0" />
            <geometry>
                <mesh filename="package://open_manipulator_6dof_description/meshes/chain_link3.stl" scale="0.001 0.001 0.001" />
            </geometry>
        </collision>
        <inertial>
            <origin xyz="0 0 0" rpy="0 0 0" />
            <mass value="0.131" />
            <inertia ixx="0.1" ixy="0.0" ixz="0.0" iyy="0.1" iyz="0.0" izz="0.1" />
        </inertial>
    </link>
    <!--  Joint 3 -->
    <joint name="sara_2_joint3" type="revolute">
        <parent link="sara_2_link3" />
        <child link="sara_2_link4" />
        <origin rpy="0 0 0" xyz="0.0 0 0.124" />
        <axis xyz="0 1 0" />
        <limit effort="1" lower="-1.8849555921538759" upper="2.1362830044410597" velocity="4.8" />
    </joint>
    <!--  Link 4 -->
    <link name="sara_2_link4">
        <visual>
            <origin rpy="0 0 0" xyz="0 0 0" />
            <geometry>
                <mesh filename="package://open_manipulator_6dof_description/meshes/chain_link4.stl" scale="0.001 0.001 0.001" />
            </geometry>
            <material name="grey" />
        </visual>
        <collision>
            <origin rpy="0 0 0" xyz="0 0 0" />
            <geometry>
                <mesh filename="package://open_manipulator_6dof_description/meshes/chain_link4.stl" scale="0.001 0.001 0.001" />
            </geometry>
        </collision>
        <inertial>
            <origin xyz="0 0 0" rpy="0 0 0" />
            <mass value="0.098" />
            <inertia ixx="0.1" ixy="0.0" ixz="0.0" iyy="0.1" iyz="0.0" izz="0.1" />
        </inertial>
    </link>
    <!--  Joint 4 -->
    <joint name="sara_2_joint4" type="revolute">
        <parent link="sara_2_link4" />
        <child link="sara_2_link5" />
        <origin rpy="0 0 0" xyz="0.0 0.0 0.045" />
        <axis xyz="0 0 1" />
        <limit effort="1" lower="-2.827433388230814" upper="2.827433388230814" velocity="4.8" />
    </joint>
    <!--  Link 5 -->
    <link name="sara_2_link5">
        <visual>
            <origin rpy="0 0 0" xyz="0 0 0.019" />
            <geometry>
                <mesh filename="package://open_manipulator_6dof_description/meshes/chain_link5.stl" scale="0.001 0.001 0.001" />
            </geometry>
            <material name="grey" />
        </visual>
        <collision>
            <origin rpy="0 0 0" xyz="0 0 0.019" />
            <geometry>
                <mesh filename="package://open_manipulator_6dof_description/meshes/chain_link5.stl" scale="0.001 0.001 0.001" />
            </geometry>
        </collision>
        <inertial>
            <origin xyz="0 0 0" rpy="0 0 0" />
            <mass value="0.098" />
            <inertia ixx="0.1" ixy="0.0" ixz="0.0" iyy="0.1" iyz="0.0" izz="0.1" />
        </inertial>
    </link>
    <!--  Joint 5 -->
    <joint name="sara_2_joint5" type="revolute">
        <parent link="sara_2_link5" />
        <child link="sara_2_link6" />
        <origin rpy="0 0 0" xyz="0.0 0.0 0.0595" />
        <axis xyz="0 1 0" />
        <limit effort="1" lower="-1.9792033717615696" upper="2.1048670779051615" velocity="4.8" />
    </joint>
    <!--  Link 6 -->
    <link name="sara_2_link6">
        <visual>
            <origin rpy="0 0 0" xyz="0 0 0.0" />
            <geometry>
                <mesh filename="package://open_manipulator_6dof_description/meshes/chain_link6.stl" scale="0.001 0.001 0.001" />
            </geometry>
            <material name="grey" />
        </visual>
        <collision>
            <origin rpy="0 0 0" xyz="0 0 0.0" />
            <geometry>
                <mesh filename="package://open_manipulator_6dof_description/meshes/chain_link6.stl" scale="0.001 0.001 0.001" />
            </geometry>
        </collision>
        <inertial>
            <origin xyz="0 0 0" rpy="0 0 0" />
            <mass value="0.033" />
            <inertia ixx="0.1" ixy="0.0" ixz="0.0" iyy="0.1" iyz="0.0" izz="0.1" />
        </inertial>
        <inertial>
            <origin xyz="4.4206755e-02 3.6839985e-07 8.9142216e-03" />
            <mass value="1.4327573e-01" />
            <inertia ixx="8.0870749e-05" ixy="0.0" ixz="-1.0157896e-06" iyy="7.5980465e-05" iyz="0.0" izz="9.3127351e-05" />
        </inertial>
    </link>
    <!--  Joint 6 -->
    <joint name="sara_2_joint6" type="revolute">
        <parent link="sara_2_link6" />
        <child link="sara_2_link7" />
        <origin rpy="0 0 0" xyz="0.0 0.0 0.0475" />
        <axis xyz="0 0 1" />
        <limit effort="1" lower="-2.827433388230814" upper="2.827433388230814" velocity="4.8" />
    </joint>
    <!--  Link 7 -->
    <link name="sara_2_link7">
        <visual>
            <origin rpy="0 0 0" xyz="0 0 0.0" />
            <geometry>
                <mesh filename="package://open_manipulator_6dof_description/meshes/chain_link7.stl" scale="0.001 0.001 0.001" />
            </geometry>
            <!-- <material name="grey"/> -->
        </visual>
        <collision>
            <origin rpy="0 0 0" xyz="0 0 0.0" />
            <geometry>
                <mesh filename="package://open_manipulator_6dof_description/meshes/chain_link7.stl" scale="0.001 0.001 0.001" />
            </geometry>
        </collision>
        <inertial>
            <origin xyz="4.4206755e-02 3.6839985e-07 8.9142216e-03" rpy="0 0 0" />
            <mass value="1.4327573e-01" />
            <inertia ixx="8.0870749e-05" ixy="0.0" ixz="-1.0157896e-06" iyy="7.5980465e-05" iyz="0.0" izz="9.3127351e-05" />
        </inertial>
    </link>
    <!--  Gripper link -->
    <link name="sara_2_gripper_link">
        <visual>
            <origin rpy="0 0 0" xyz="0.0 0.0 0" />
            <geometry>
                <mesh filename="package://open_manipulator_6dof_description/meshes/chain_link_grip_l.stl" scale="0.001 0.001 0.001" />
            </geometry>
            <material name="grey" />
        </visual>
        <collision>
            <origin rpy="0 0 0" xyz="0.0 0.0 0" />
            <geometry>
                <mesh filename="package://open_manipulator_6dof_description/meshes/chain_link_grip_l.stl" scale="0.001 0.001 0.001" />
            </geometry>
        </collision>
        <inertial>
            <origin xyz="0 0 0" rpy="0 0 0" />
            <mass value="1.0e-03" />
            <inertia ixx="1.0e-03" ixy="0.0" ixz="0.0" iyy="1.0e-03" iyz="0.0" izz="1.0e-03" />
        </inertial>
    </link>
    <!--  Gripper joint -->
    <joint name="sara_2_gripper" type="prismatic">
        <parent link="sara_2_link7" />
        <child link="sara_2_gripper_link" />
        <origin rpy="0 0 0" xyz="0.0 0.021 0.0707" />
        <axis xyz="0 1 0" />
        <limit effort="1" lower="-0.010" upper="0.019" velocity="4.8" />
    </joint>
    <!--  Gripper link sub -->
    <link name="sara_2_gripper_link_sub">
        <visual>
            <origin rpy="0 0 0" xyz="0.0 -0.0 0" />
            <geometry>
                <mesh filename="package://open_manipulator_6dof_description/meshes/chain_link_grip_r.stl" scale="0.001 0.001 0.001" />
            </geometry>
            <material name="grey" />
        </visual>
        <collision>
            <origin rpy="0 0 0" xyz="0.0 -0.0 0" />
            <geometry>
                <mesh filename="package://open_manipulator_6dof_description/meshes/chain_link_grip_r.stl" scale="0.001 0.001 0.001" />
            </geometry>
        </collision>
        <inertial>
            <origin xyz="0 0 0" rpy="0 0 0" />
            <mass value="1.0e-03" />
            <inertia ixx="1.0e-03" ixy="0.0" ixz="0.0" iyy="1.0e-03" iyz="0.0" izz="1.0e-03" />
        </inertial>
    </link>
    <!--  Gripper joint sub -->
    <joint name="sara_2_gripper_sub" type="prismatic">
        <parent link="sara_2_link7" />
        <child link="sara_2_gripper_link_sub" />
        <origin rpy="0 0 0" xyz="0.0 -0.021 0.0707" />
        <axis xyz="0 -1 0" />
        <limit effort="1" lower="-0.010" upper="0.019" velocity="4.8" />
        <mimic joint="sara_2_gripper" multiplier="1" />
    </joint>
    <!-- end effector joint -->
    <joint name="sara_2_end_effector_joint" type="fixed">
        <origin rpy="0 0 0" xyz="0.0 0.0 0.115" />
        <parent link="sara_2_link7" />
        <child link="sara_2_end_effector_link" />
    </joint>
    <!-- end effector link -->
    <link name="sara_2_end_effector_link">
        <visual>
            <origin rpy="0 0 0" xyz="0 0 0" />
            <geometry>
                <box size="0.01 0.01 0.01" />
            </geometry>
            <material name="red" />
        </visual>
        <inertial>
            <origin xyz="0 0 0" />
            <mass value="1.0e-03" />
            <inertia ixx="1.0e-03" ixy="0.0" ixz="0.0" iyy="1.0e-03" iyz="0.0" izz="1.0e-03" />
        </inertial>
    </link>
    <transmission name="tran1">
        <type>transmission_interface/SimpleTransmission</type>
        <joint name="sara_1_joint1">
            <hardwareInterface>hardware_interface/PositionJointInterface</hardwareInterface>
        </joint>
        <actuator name="motor1">
            <hardwareInterface>hardware_interface/PositionJointInterface</hardwareInterface>
            <mechanicalReduction>1</mechanicalReduction>
        </actuator>
    </transmission>
    <transmission name="tran2">
        <type>transmission_interface/SimpleTransmission</type>
        <joint name="sara_1_joint2">
            <hardwareInterface>hardware_interface/PositionJointInterface</hardwareInterface>
        </joint>
        <actuator name="motor2">
            <hardwareInterface>hardware_interface/PositionJointInterface</hardwareInterface>
            <mechanicalReduction>1</mechanicalReduction>
        </actuator>
    </transmission>
    <transmission name="tran3">
        <type>transmission_interface/SimpleTransmission</type>
        <joint name="sara_1_joint3">
            <hardwareInterface>hardware_interface/PositionJointInterface</hardwareInterface>
        </joint>
        <actuator name="motor3">
            <hardwareInterface>hardware_interface/PositionJointInterface</hardwareInterface>
            <mechanicalReduction>1</mechanicalReduction>
        </actuator>
    </transmission>
    <transmission name="tran4">
        <type>transmission_interface/SimpleTransmission</type>
        <joint name="sara_1_joint4">
            <hardwareInterface>hardware_interface/PositionJointInterface</hardwareInterface>
        </joint>
        <actuator name="motor4">
            <hardwareInterface>hardware_interface/PositionJointInterface</hardwareInterface>
            <mechanicalReduction>1</mechanicalReduction>
        </actuator>
    </transmission>
    <transmission name="tran5">
        <type>transmission_interface/SimpleTransmission</type>
        <joint name="sara_1_joint5">
            <hardwareInterface>hardware_interface/PositionJointInterface</hardwareInterface>
        </joint>
        <actuator name="motor5">
            <hardwareInterface>hardware_interface/PositionJointInterface</hardwareInterface>
            <mechanicalReduction>1</mechanicalReduction>
        </actuator>
    </transmission>
    <transmission name="tran6">
        <type>transmission_interface/SimpleTransmission</type>
        <joint name="sara_1_joint6">
            <hardwareInterface>hardware_interface/PositionJointInterface</hardwareInterface>
        </joint>
        <actuator name="motor6">
            <hardwareInterface>hardware_interface/PositionJointInterface</hardwareInterface>
            <mechanicalReduction>1</mechanicalReduction>
        </actuator>
    </transmission>
    <transmission name="tran7">
        <type>transmission_interface/SimpleTransmission</type>
        <joint name="sara_1_joint7">
            <hardwareInterface>hardware_interface/PositionJointInterface</hardwareInterface>
        </joint>
        <actuator name="motor7">
            <hardwareInterface>hardware_interface/PositionJointInterface</hardwareInterface>
            <mechanicalReduction>1</mechanicalReduction>
        </actuator>
    </transmission>
    <transmission name="tran8">
        <type>transmission_interface/SimpleTransmission</type>
        <joint name="sara_2_joint1">
            <hardwareInterface>hardware_interface/PositionJointInterface</hardwareInterface>
        </joint>
        <actuator name="motor8">
            <hardwareInterface>hardware_interface/PositionJointInterface</hardwareInterface>
            <mechanicalReduction>1</mechanicalReduction>
        </actuator>
    </transmission>
    <transmission name="tran9">
        <type>transmission_interface/SimpleTransmission</type>
        <joint name="sara_2_joint2">
            <hardwareInterface>hardware_interface/PositionJointInterface</hardwareInterface>
        </joint>
        <actuator name="motor9">
            <hardwareInterface>hardware_interface/PositionJointInterface</hardwareInterface>
            <mechanicalReduction>1</mechanicalReduction>
        </actuator>
    </transmission>
    <transmission name="tran10">
        <type>transmission_interface/SimpleTransmission</type>
        <joint name="sara_2_joint3">
            <hardwareInterface>hardware_interface/PositionJointInterface</hardwareInterface>
        </joint>
        <actuator name="motor10">
            <hardwareInterface>hardware_interface/PositionJointInterface</hardwareInterface>
            <mechanicalReduction>1</mechanicalReduction>
        </actuator>
    </transmission>
    <transmission name="tran11">
        <type>transmission_interface/SimpleTransmission</type>
        <joint name="sara_2_joint4">
            <hardwareInterface>hardware_interface/PositionJointInterface</hardwareInterface>
        </joint>
        <actuator name="motor11">
            <hardwareInterface>hardware_interface/PositionJointInterface</hardwareInterface>
            <mechanicalReduction>1</mechanicalReduction>
        </actuator>
    </transmission>
    <transmission name="tran12">
        <type>transmission_interface/SimpleTransmission</type>
        <joint name="sara_2_joint5">
            <hardwareInterface>hardware_interface/PositionJointInterface</hardwareInterface>
        </joint>
        <actuator name="motor12">
            <hardwareInterface>hardware_interface/PositionJointInterface</hardwareInterface>
            <mechanicalReduction>1</mechanicalReduction>
        </actuator>
    </transmission>
    <transmission name="tran13">
        <type>transmission_interface/SimpleTransmission</type>
        <joint name="sara_2_joint6">
            <hardwareInterface>hardware_interface/PositionJointInterface</hardwareInterface>
        </joint>
        <actuator name="motor13">
            <hardwareInterface>hardware_interface/PositionJointInterface</hardwareInterface>
            <mechanicalReduction>1</mechanicalReduction>
        </actuator>
    </transmission>
    <transmission name="tran14">
        <type>transmission_interface/SimpleTransmission</type>
        <joint name="sara_2_joint7">
            <hardwareInterface>hardware_interface/PositionJointInterface</hardwareInterface>
        </joint>
        <actuator name="motor14">
            <hardwareInterface>hardware_interface/PositionJointInterface</hardwareInterface>
            <mechanicalReduction>1</mechanicalReduction>
        </actuator>
    </transmission>
    <transmission name="tran15">
        <type>transmission_interface/SimpleTransmission</type>
        <joint name="sara_1_Gripper_link">
            <hardwareInterface>hardware_interface/EffortJointInterface</hardwareInterface>
        </joint>
        <actuator name="motor15">
            <hardwareInterface>hardware_interface/EffortJointInterface</hardwareInterface>
            <mechanicalReduction>1</mechanicalReduction>
        </actuator>
    </transmission>
    <transmission name="tran16">
        <type>transmission_interface/SimpleTransmission</type>
        <joint name="sara_1_Gripper_joint">
            <hardwareInterface>hardware_interface/EffortJointInterface</hardwareInterface>
        </joint>
        <actuator name="motor16">
            <hardwareInterface>hardware_interface/EffortJointInterface</hardwareInterface>
            <mechanicalReduction>1</mechanicalReduction>
        </actuator>
    </transmission>
    <transmission name="tran17">
        <type>transmission_interface/SimpleTransmission</type>
        <joint name="sara_1_Gripper_link_sub">
            <hardwareInterface>hardware_interface/EffortJointInterface</hardwareInterface>
        </joint>
        <actuator name="motor17">
            <hardwareInterface>hardware_interface/EffortJointInterface</hardwareInterface>
            <mechanicalReduction>1</mechanicalReduction>
        </actuator>
    </transmission>
    <transmission name="tran18">
        <type>transmission_interface/SimpleTransmission</type>
        <joint name="sara_1_Gripper_joint_sub">
            <hardwareInterface>hardware_interface/EffortJointInterface</hardwareInterface>
        </joint>
        <actuator name="motor18">
            <hardwareInterface>hardware_interface/EffortJointInterface</hardwareInterface>
            <mechanicalReduction>1</mechanicalReduction>
        </actuator>
    </transmission>
    <transmission name="tran19">
        <type>transmission_interface/SimpleTransmission</type>
        <joint name="sara_1_end_effector_joint">
            <hardwareInterface>hardware_interface/EffortJointInterface</hardwareInterface>
        </joint>
        <actuator name="motor19">
            <hardwareInterface>hardware_interface/EffortJointInterface</hardwareInterface>
            <mechanicalReduction>1</mechanicalReduction>
        </actuator>
    </transmission>
    <transmission name="tran20">
        <type>transmission_interface/SimpleTransmission</type>
        <joint name="sara_1_end_effector_link">
            <hardwareInterface>hardware_interface/EffortJointInterface</hardwareInterface>
        </joint>
        <actuator name="motor20">
            <hardwareInterface>hardware_interface/EffortJointInterface</hardwareInterface>
            <mechanicalReduction>1</mechanicalReduction>
        </actuator>
    </transmission>
    <transmission name="tran21">
        <type>transmission_interface/SimpleTransmission</type>
        <joint name="sara_2_Gripper_link">
            <hardwareInterface>hardware_interface/EffortJointInterface</hardwareInterface>
        </joint>
        <actuator name="motor21">
            <hardwareInterface>hardware_interface/EffortJointInterface</hardwareInterface>
            <mechanicalReduction>1</mechanicalReduction>
        </actuator>
    </transmission>
    <transmission name="tran22">
        <type>transmission_interface/SimpleTransmission</type>
        <joint name="sara_2_Gripper_joint">
            <hardwareInterface>hardware_interface/EffortJointInterface</hardwareInterface>
        </joint>
        <actuator name="motor22">
            <hardwareInterface>hardware_interface/EffortJointInterface</hardwareInterface>
            <mechanicalReduction>1</mechanicalReduction>
        </actuator>
    </transmission>
    <transmission name="tran23">
        <type>transmission_interface/SimpleTransmission</type>
        <joint name="sara_2_Gripper_link_sub">
            <hardwareInterface>hardware_interface/EffortJointInterface</hardwareInterface>
        </joint>
        <actuator name="motor23">
            <hardwareInterface>hardware_interface/EffortJointInterface</hardwareInterface>
            <mechanicalReduction>1</mechanicalReduction>
        </actuator>
    </transmission>
    <transmission name="tran24">
        <type>transmission_interface/SimpleTransmission</type>
        <joint name="sara_2_Gripper_joint_sub">
            <hardwareInterface>hardware_interface/EffortJointInterface</hardwareInterface>
        </joint>
        <actuator name="motor24">
            <hardwareInterface>hardware_interface/EffortJointInterface</hardwareInterface>
            <mechanicalReduction>1</mechanicalReduction>
        </actuator>
    </transmission>
    <transmission name="tran25">
        <type>transmission_interface/SimpleTransmission</type>
        <joint name="sara_2_end_effector_joint">
            <hardwareInterface>hardware_interface/EffortJointInterface</hardwareInterface>
        </joint>
        <actuator name="motor25">
            <hardwareInterface>hardware_interface/EffortJointInterface</hardwareInterface>
            <mechanicalReduction>1</mechanicalReduction>
        </actuator>
    </transmission>
    <transmission name="tran26">
        <type>transmission_interface/SimpleTransmission</type>
        <joint name="sara_2_end_effector_link">
            <hardwareInterface>hardware_interface/EffortJointInterface</hardwareInterface>
        </joint>
        <actuator name="motor26">
            <hardwareInterface>hardware_interface/EffortJointInterface</hardwareInterface>
            <mechanicalReduction>1</mechanicalReduction>
        </actuator>
    </transmission>
    <!-- load ros_control plugin -->
    <gazebo>
        <plugin filename="libgazebo_ros_control.so" name="gazebo_ros_control">
            <robotNamespace>/</robotNamespace>
        </plugin>
    </gazebo>
    <transmission name="trans_sara_1_gripper">
        <type>transmission_interface/SimpleTransmission</type>
        <joint name="sara_1_gripper">
            <hardwareInterface>hardware_interface/EffortJointInterface</hardwareInterface>
        </joint>
        <actuator name="sara_1_gripper_motor">
            <hardwareInterface>hardware_interface/EffortJointInterface</hardwareInterface>
            <mechanicalReduction>1</mechanicalReduction>
        </actuator>
    </transmission>
    <transmission name="trans_sara_1_gripper_sub">
        <type>transmission_interface/SimpleTransmission</type>
        <joint name="sara_1_gripper_sub">
            <hardwareInterface>hardware_interface/EffortJointInterface</hardwareInterface>
        </joint>
        <actuator name="sara_1_gripper_sub_motor">
            <hardwareInterface>hardware_interface/EffortJointInterface</hardwareInterface>
            <mechanicalReduction>1</mechanicalReduction>
        </actuator>
    </transmission>
    <transmission name="trans_sara_2_gripper">
        <type>transmission_interface/SimpleTransmission</type>
        <joint name="sara_2_gripper">
            <hardwareInterface>hardware_interface/EffortJointInterface</hardwareInterface>
        </joint>
        <actuator name="sara_2_gripper_motor">
            <hardwareInterface>hardware_interface/EffortJointInterface</hardwareInterface>
            <mechanicalReduction>1</mechanicalReduction>
        </actuator>
    </transmission>
    <transmission name="trans_sara_2_gripper_sub">
        <type>transmission_interface/SimpleTransmission</type>
        <joint name="sara_2_gripper_sub">
            <hardwareInterface>hardware_interface/EffortJointInterface</hardwareInterface>
        </joint>
        <actuator name="sara_2_gripper_sub_motor">
            <hardwareInterface>hardware_interface/EffortJointInterface</hardwareInterface>
            <mechanicalReduction>1</mechanicalReduction>
        </actuator>
    </transmission>
</robot>

